Traceback (most recent call last):
  File "/mnt/home/rsilva/Documents/miniconda3/envs/datascience/lib/python3.12/site-packages/jupyter_cache/executors/utils.py", line 58, in single_nb_execution
    executenb(
  File "/mnt/home/rsilva/Documents/miniconda3/envs/datascience/lib/python3.12/site-packages/nbclient/client.py", line 1314, in execute
    return NotebookClient(nb=nb, resources=resources, km=km, **kwargs).execute()
           ^^^^^^^^^^^^^^^^^^^^^^^^^^^^^^^^^^^^^^^^^^^^^^^^^^^^^^^^^^^^^^^^^^^^^
  File "/mnt/home/rsilva/Documents/miniconda3/envs/datascience/lib/python3.12/site-packages/jupyter_core/utils/__init__.py", line 165, in wrapped
    return loop.run_until_complete(inner)
           ^^^^^^^^^^^^^^^^^^^^^^^^^^^^^^
  File "/mnt/home/rsilva/Documents/miniconda3/envs/datascience/lib/python3.12/asyncio/base_events.py", line 687, in run_until_complete
    return future.result()
           ^^^^^^^^^^^^^^^
  File "/mnt/home/rsilva/Documents/miniconda3/envs/datascience/lib/python3.12/site-packages/nbclient/client.py", line 709, in async_execute
    await self.async_execute_cell(
  File "/mnt/home/rsilva/Documents/miniconda3/envs/datascience/lib/python3.12/site-packages/nbclient/client.py", line 1062, in async_execute_cell
    await self._check_raise_for_error(cell, cell_index, exec_reply)
  File "/mnt/home/rsilva/Documents/miniconda3/envs/datascience/lib/python3.12/site-packages/nbclient/client.py", line 918, in _check_raise_for_error
    raise CellExecutionError.from_cell_and_msg(cell, exec_reply_content)
nbclient.exceptions.CellExecutionError: An error occurred while executing the following cell:
------------------
from sklearn.cluster import AgglomerativeClustering
cluster = AgglomerativeClustering(n_clusters=3, affinity='euclidean', linkage='ward')  
cluster.fit_predict(x)
------------------


[0;31m---------------------------------------------------------------------------[0m
[0;31mTypeError[0m                                 Traceback (most recent call last)
Cell [0;32mIn[16], line 2[0m
[1;32m      1[0m [38;5;28;01mfrom[39;00m [38;5;21;01msklearn[39;00m[38;5;21;01m.[39;00m[38;5;21;01mcluster[39;00m [38;5;28;01mimport[39;00m AgglomerativeClustering
[0;32m----> 2[0m cluster [38;5;241m=[39m [43mAgglomerativeClustering[49m[43m([49m[43mn_clusters[49m[38;5;241;43m=[39;49m[38;5;241;43m3[39;49m[43m,[49m[43m [49m[43maffinity[49m[38;5;241;43m=[39;49m[38;5;124;43m'[39;49m[38;5;124;43meuclidean[39;49m[38;5;124;43m'[39;49m[43m,[49m[43m [49m[43mlinkage[49m[38;5;241;43m=[39;49m[38;5;124;43m'[39;49m[38;5;124;43mward[39;49m[38;5;124;43m'[39;49m[43m)[49m  
[1;32m      3[0m cluster[38;5;241m.[39mfit_predict(x)

[0;31mTypeError[0m: AgglomerativeClustering.__init__() got an unexpected keyword argument 'affinity'

